<?xml version="1.0" encoding="utf-8"?>
<!-- =================================================================================== -->
<!-- |    This document was autogenerated by xacro from spear_simulator/models/rover/arm.urdf.xacro | -->
<!-- |    EDITING THIS FILE BY HAND IS NOT RECOMMENDED                                 | -->
<!-- =================================================================================== -->
<robot name="arm">
  <joint name="arm_mount" type="fixed">
    <parent link="base_link"/>
    <child link="arm_mount"/>
    <origin xyz="0.25 0 0.3"/>
  </joint>
  <link name="arm_mount">
  </link>
  <joint name="shoulder_yaw" type="revolute">
    <parent link="arm_mount"/>
    <child link="shoulder"/>
    <axis xyz="0 0 1"/>
    <origin rpy="0 0 3.14" xyz="0 0 0"/>
    <limit effort="1" lower="-3.15" upper="3.15" velocity="0.5"/>
  </joint>
  <transmission name="shoulder_yaw_trans">
    <type>transmission_interface/SimpleTransmission</type>
    <actuator name="shoulder_yaw_actuator">
      <hardwareInterface>hardware_interface/PositionJointInterface</hardwareInterface>
      <mechanicalReduction>1</mechanicalReduction>
    </actuator>
    <joint name="shoulder_yaw">
      <hardwareInterface>hardware_interface/PositionJointInterface</hardwareInterface>
    </joint>
  </transmission>
  <link name="shoulder">
    <visual>
      <origin rpy="0 0 0" xyz="0 0 0.045"/>
      <geometry>
        <cylinder length="0.085" radius="0.05"/>
      </geometry>
    </visual>
  </link>
  <joint name="shoulder_pitch" type="revolute">
    <parent link="shoulder"/>
    <child link="bicep"/>
    <axis xyz="0 1 0"/>
    <origin rpy="0 0 0" xyz="0 0 0.09"/>
    <limit effort="1" lower="0.78" upper="2.15" velocity="0.5"/>
  </joint>
  <transmission name="shoulder_pitch_trans">
    <type>transmission_interface/SimpleTransmission</type>
    <actuator name="shoulder_pitch_actuator">
      <hardwareInterface>hardware_interface/PositionJointInterface</hardwareInterface>
      <mechanicalReduction>1</mechanicalReduction>
    </actuator>
    <joint name="shoulder_pitch">
      <hardwareInterface>hardware_interface/PositionJointInterface</hardwareInterface>
    </joint>
  </transmission>
  <link name="bicep">
    <visual>
      <origin rpy="0 0 0" xyz="0 0 0.1775"/>
      <geometry>
        <cylinder length="0.35" radius="0.05"/>
      </geometry>
    </visual>
  </link>
  <joint name="elbow_pitch" type="revolute">
    <parent link="bicep"/>
    <child link="forearm"/>
    <axis xyz="0 1 0"/>
    <origin rpy="0 0 0" xyz="0 0 0.355"/>
    <limit effort="1" lower="-2.7" upper="1.54" velocity="0.5"/>
  </joint>
  <transmission name="elbow_pitch_trans">
    <type>transmission_interface/SimpleTransmission</type>
    <actuator name="elbow_pitch_actuator">
      <hardwareInterface>hardware_interface/PositionJointInterface</hardwareInterface>
      <mechanicalReduction>1</mechanicalReduction>
    </actuator>
    <joint name="elbow_pitch">
      <hardwareInterface>hardware_interface/PositionJointInterface</hardwareInterface>
    </joint>
  </transmission>
  <link name="forearm">
    <visual>
      <origin rpy="0 0 0" xyz="0 0 0.0925"/>
      <geometry>
        <cylinder length="0.18" radius="0.05"/>
      </geometry>
    </visual>
  </link>
  <joint name="wrist_pitch" type="revolute">
    <parent link="forearm"/>
    <child link="wrist"/>
    <axis xyz="0 1 0"/>
    <origin rpy="0 0 0" xyz="0 0 0.185"/>
    <limit effort="1" lower="-2.09" upper="2.09" velocity="0.5"/>
  </joint>
  <transmission name="wrist_pitch_trans">
    <type>transmission_interface/SimpleTransmission</type>
    <actuator name="wrist_pitch_actuator">
      <hardwareInterface>hardware_interface/PositionJointInterface</hardwareInterface>
      <mechanicalReduction>1</mechanicalReduction>
    </actuator>
    <joint name="wrist_pitch">
      <hardwareInterface>hardware_interface/PositionJointInterface</hardwareInterface>
    </joint>
  </transmission>
  <link name="wrist">
    <visual>
      <origin rpy="0 0 0" xyz="0 0 0.0185"/>
      <geometry>
        <cylinder length="0.032" radius="0.05"/>
      </geometry>
    </visual>
  </link>
  <joint name="wrist_roll" type="revolute">
    <parent link="wrist"/>
    <child link="palm"/>
    <axis xyz="0 0 1"/>
    <origin rpy="0 0 0" xyz="0 0 0.037"/>
    <limit effort="1" lower="-3" upper="3" velocity="0.5"/>
  </joint>
  <transmission name="wrist_roll_trans">
    <type>transmission_interface/SimpleTransmission</type>
    <actuator name="wrist_roll_actuator">
      <hardwareInterface>hardware_interface/PositionJointInterface</hardwareInterface>
      <mechanicalReduction>1</mechanicalReduction>
    </actuator>
    <joint name="wrist_roll">
      <hardwareInterface>hardware_interface/PositionJointInterface</hardwareInterface>
    </joint>
  </transmission>
  <link name="palm">
    <visual>
      <origin rpy="0 0 0" xyz="0 0 0.023125"/>
      <geometry>
        <cylinder length="0.04125" radius="0.05"/>
      </geometry>
    </visual>
  </link>
  <joint name="grab" type="revolute">
    <parent link="palm"/>
    <child link="finger"/>
    <axis xyz="1 0 0"/>
    <origin xyz="0 0 0.04625"/>
    <limit effort="1" lower="-1" upper="1" velocity="0.5"/>
  </joint>
  <transmission name="grab_trans">
    <type>transmission_interface/SimpleTransmission</type>
    <actuator name="grab_actuator">
      <hardwareInterface>hardware_interface/PositionJointInterface</hardwareInterface>
      <mechanicalReduction>1</mechanicalReduction>
    </actuator>
    <joint name="grab">
      <hardwareInterface>hardware_interface/PositionJointInterface</hardwareInterface>
    </joint>
  </transmission>
  <link name="finger">
    <visual>
      <origin rpy="0 0 0" xyz="0 0 0.0308333333333"/>
      <geometry>
        <cylinder length="0.0566666666667" radius="0.05"/>
      </geometry>
    </visual>
  </link>
</robot>

