<?xml version="1.0"?>
<!-- created with Phobos 0.8 -->
  <robot name="TARS_V2">

    <link name="link_camera_back">
    </link>

    <link name="link_camera_depth">
    </link>

    <link name="link_camera_front">
    </link>

    <link name="link_chassis">
      <inertial>
        <origin xyz="0 0 0.19608" rpy="0 0 0"/>
        <mass value="30.0"/>
        <inertia ixx="0.79449" ixy="0" ixz="0" iyy="1.21074" iyz="0" izz="1.56825"/>
      </inertial>
      <visual name="visual_chassis">
        <origin xyz="0 0 0" rpy="0 0 0"/>
        <geometry>
          <mesh filename="..\meshes\stl\TARS.V2.Chassis.stl" scale="0.001 0.001 0.001"/>
        </geometry>
      </visual>
      <collision name="collision_chassis">
        <origin xyz="0 0 0.19608" rpy="0 0 0"/>
        <geometry>
          <box size="0.63 0.48 0.29562"/>
        </geometry>
      </collision>
    </link>

    <link name="link_suspension_backleft">
      <inertial>
        <origin xyz="-0.12007 -0.01981 -0.04013" rpy="0 0 0"/>
        <mass value="0.75"/>
        <inertia ixx="0.00147" ixy="0" ixz="0" iyy="0.00598" iyz="0" izz="0.00469"/>
      </inertial>
      <visual name="visual_suspension_backleft">
        <origin xyz="0 0 0" rpy="0 0 0"/>
        <geometry>
          <mesh filename="..\meshes\stl\TARS.V2.Suspension.004.stl" scale="0.001 0.001 0.001"/>
        </geometry>
      </visual>
      <collision name="collision_suspension_backleft">
        <origin xyz="-0.12007 -0.01981 -0.04013" rpy="0 0 0"/>
        <geometry>
          <box size="0.27135 0.0381 0.14844"/>
        </geometry>
      </collision>
    </link>

    <link name="link_suspension_backright">
      <inertial>
        <origin xyz="-0.12007 0.02019 -0.04013" rpy="0 0 0"/>
        <mass value="0.75"/>
        <inertia ixx="0.00147" ixy="0" ixz="0" iyy="0.00598" iyz="0" izz="0.00469"/>
      </inertial>
      <visual name="visual_suspension_backright">
        <origin xyz="0 0 0" rpy="0 0 0"/>
        <geometry>
          <mesh filename="..\meshes\stl\TARS.V2.Suspension.003.stl" scale="0.001 0.001 0.001"/>
        </geometry>
      </visual>
      <collision name="collision_suspension_backright">
        <origin xyz="-0.12007 0.02019 -0.04013" rpy="0 0 0"/>
        <geometry>
          <box size="0.27135 0.0381 0.14844"/>
        </geometry>
      </collision>
    </link>

    <link name="link_suspension_frontleft">
      <inertial>
        <origin xyz="0.12007 -0.02019 -0.04013" rpy="0 0 0"/>
        <mass value="0.75"/>
        <inertia ixx="0.00147" ixy="0" ixz="0" iyy="0.00598" iyz="0" izz="0.00469"/>
      </inertial>
      <visual name="visual_suspension_frontleft">
        <origin xyz="0 0 0" rpy="0 0 0"/>
        <geometry>
          <mesh filename="..\meshes\stl\TARS.V2.Suspension.001.stl" scale="0.001 0.001 0.001"/>
        </geometry>
      </visual>
      <collision name="collision_suspension_frontleft">
        <origin xyz="0.12007 -0.02019 -0.04013" rpy="0 0 0"/>
        <geometry>
          <box size="0.27135 0.0381 0.14844"/>
        </geometry>
      </collision>
    </link>

    <link name="link_suspension_frontright">
      <inertial>
        <origin xyz="0.12007 0.01981 -0.04013" rpy="0 0 0"/>
        <mass value="0.75"/>
        <inertia ixx="0.00147" ixy="0" ixz="0" iyy="0.00598" iyz="0" izz="0.00469"/>
      </inertial>
      <visual name="visual_suspension_frontright">
        <origin xyz="0 0 0" rpy="0 0 0"/>
        <geometry>
          <mesh filename="..\meshes\stl\TARS.V2.Suspension.002.stl" scale="0.001 0.001 0.001"/>
        </geometry>
      </visual>
      <collision name="collision_suspension_frontright">
        <origin xyz="0.12007 0.01981 -0.04013" rpy="0 0 0"/>
        <geometry>
          <box size="0.27134 0.0381 0.14845"/>
        </geometry>
      </collision>
    </link>

    <link name="link_wheel_backleft">
      <inertial>
        <origin xyz="0 0.10244 0" rpy="0 0 0"/>
        <mass value="1.5"/>
        <inertia ixx="0.01534" ixy="0" ixz="0" iyy="0.01534" iyz="0" izz="0.01534"/>
      </inertial>
      <visual name="visual_wheel_backleft">
        <origin xyz="0 0 0" rpy="0 0 0"/>
        <geometry>
          <mesh filename="..\meshes\stl\TARS.V2.Wheels.004.stl" scale="0.001 0.001 0.001"/>
        </geometry>
      </visual>
      <collision name="collision_wheel_backleft">
        <origin xyz="0 0.10244 0" rpy="0 0 0"/>
        <geometry>
          <sphere radius="0.15989"/>
        </geometry>
      </collision>
    </link>

    <link name="link_wheel_backright">
      <inertial>
        <origin xyz="0 -0.10254 0" rpy="0 0 0"/>
        <mass value="1.5"/>
        <inertia ixx="0.01534" ixy="0" ixz="0" iyy="0.01534" iyz="0" izz="0.01534"/>
      </inertial>
      <visual name="visual_wheel_backright">
        <origin xyz="0 0 0" rpy="0 0 0"/>
        <geometry>
          <mesh filename="..\meshes\stl\TARS.V2.Wheels.003.stl" scale="0.001 0.001 0.001"/>
        </geometry>
      </visual>
      <collision name="collision_wheel_backright">
        <origin xyz="0 -0.10254 0" rpy="0 0 0"/>
        <geometry>
          <sphere radius="0.15989"/>
        </geometry>
      </collision>
    </link>

    <link name="link_wheel_frontleft">
      <inertial>
        <origin xyz="0 0.10244 0" rpy="0 0 0"/>
        <mass value="1.5"/>
        <inertia ixx="0.01534" ixy="0" ixz="0" iyy="0.01534" iyz="0" izz="0.01534"/>
      </inertial>
      <visual name="visual_wheel_frontleft">
        <origin xyz="0 0 0" rpy="0 0 0"/>
        <geometry>
          <mesh filename="..\meshes\stl\TARS.V2.Wheel.001.stl" scale="0.001 0.001 0.001"/>
        </geometry>
      </visual>
      <collision name="collision_wheel_frontleft">
        <origin xyz="0 0.10244 0" rpy="0 0 0"/>
        <geometry>
          <sphere radius="0.15989"/>
        </geometry>
      </collision>
    </link>

    <link name="link_wheel_frontright">
      <inertial>
        <origin xyz="0 -0.10264 0" rpy="0 0 0"/>
        <mass value="1.5"/>
        <inertia ixx="0.01534" ixy="0" ixz="0" iyy="0.01534" iyz="0" izz="0.01534"/>
      </inertial>
      <visual name="visual_wheel_frontright">
        <origin xyz="0 0 0" rpy="0 0 0"/>
        <geometry>
          <mesh filename="..\meshes\stl\TARS.V2.Wheels.002.stl" scale="0.001 0.001 0.001"/>
        </geometry>
      </visual>
      <collision name="collision_wheel_frontright">
        <origin xyz="0 -0.10264 0" rpy="0 0 0"/>
        <geometry>
          <sphere radius="0.15989"/>
        </geometry>
      </collision>
    </link>

    <joint name="link_camera_back" type="fixed">
      <origin xyz="-0.315 1e-05 0.3439" rpy="3.14159 1.5708 0"/>
      <parent link="link_chassis"/>
      <child link="link_camera_back"/>
    </joint>

    <joint name="link_camera_depth" type="fixed">
      <origin xyz="0.315 1e-05 0.3439" rpy="0 1.5708 0"/>
      <parent link="link_chassis"/>
      <child link="link_camera_depth"/>
    </joint>

    <joint name="link_camera_front" type="fixed">
      <origin xyz="0.315 -0.11999 0.3439" rpy="0 1.5708 0"/>
      <parent link="link_chassis"/>
      <child link="link_camera_front"/>
    </joint>

    <joint name="link_suspension_backleft" type="fixed">
      <origin xyz="-0.15754 0.25888 0.07402" rpy="0 0 0"/>
      <parent link="link_chassis"/>
      <child link="link_suspension_backleft"/>
    </joint>

    <joint name="link_suspension_backright" type="fixed">
      <origin xyz="-0.15754 -0.25922 0.07402" rpy="0 0 0"/>
      <parent link="link_chassis"/>
      <child link="link_suspension_backright"/>
    </joint>

    <joint name="link_suspension_frontleft" type="fixed">
      <origin xyz="0.15754 0.25925 0.07402" rpy="0 0 0"/>
      <parent link="link_chassis"/>
      <child link="link_suspension_frontleft"/>
    </joint>

    <joint name="link_suspension_frontright" type="fixed">
      <origin xyz="0.15755 -0.25885 0.07403" rpy="0 0 0"/>
      <parent link="link_chassis"/>
      <child link="link_suspension_frontright"/>
    </joint>

    <joint name="link_wheel_backleft" type="floating">
      <origin xyz="-0.21346 0.01924 -0.08012" rpy="0 0 0"/>
      <parent link="link_suspension_backleft"/>
      <child link="link_wheel_backleft"/>
    </joint>

    <joint name="link_wheel_backright" type="floating">
      <origin xyz="-0.21346 -0.01886 -0.08012" rpy="0 0 0"/>
      <parent link="link_suspension_backright"/>
      <child link="link_wheel_backright"/>
    </joint>

    <joint name="link_wheel_frontleft" type="floating">
      <origin xyz="0.21346 0.01886 -0.08012" rpy="0 0 0"/>
      <parent link="link_suspension_frontleft"/>
      <child link="link_wheel_frontleft"/>
    </joint>

    <joint name="link_wheel_frontright" type="floating">
      <origin xyz="0.21345 -0.01924 -0.08014" rpy="0 0 0"/>
      <parent link="link_suspension_frontright"/>
      <child link="link_wheel_frontright"/>
    </joint>

  </robot>
