<?xml version="1.0"?>
<!-- created with Phobos 0.8 -->
  <robot name="TARS_V2">

    <link name="link_camera_back">
    </link>

    <link name="link_camera_depth">
    </link>

    <gazebo reference="link_camera_depth">  
      <sensor type="depth" name="camera">
        <always_on>true</always_on>
        <update_rate>20.0</update_rate>
        <camera>
          <horizontal_fov>1.57</horizontal_fov>
          <image>
            <format>B8G8R8</format>
            <width>640</width>
            <height>480</height>
          </image>
          <clip>
            <near>0.05</near>
            <far>8.0</far>
          </clip>
        </camera>
        <plugin name="kinect_camera_controller" filename="libgazebo_ros_openni_kinect.so">
          <cameraName>camera</cameraName>
          <alwaysOn>true</alwaysOn>
          <updateRate>10</updateRate>
          <imageTopicName>rgb/image_raw</imageTopicName>
          <depthImageTopicName>depth/image_raw</depthImageTopicName>
          <pointCloudTopicName>depth/points</pointCloudTopicName>
          <cameraInfoTopicName>rgb/camera_info</cameraInfoTopicName>
          <depthImageCameraInfoTopicName>depth/camera_info</depthImageCameraInfoTopicName>
          <frameName>camera_depth_optical_frame</frameName>
          <baseline>0.1</baseline>
          <distortion_k1>0.0</distortion_k1>
          <distortion_k2>0.0</distortion_k2>
          <distortion_k3>0.0</distortion_k3>
          <distortion_t1>0.0</distortion_t1>
          <distortion_t2>0.0</distortion_t2>
          <pointCloudCutoff>0.4</pointCloudCutoff>
        </plugin>
      </sensor>
    </gazebo>

    <link name="link_camera_front">
    </link>

    <link name="base_link">
      <inertial>
        <origin xyz="0 0 0.19608" rpy="0 0 0"/>
        <mass value="30.0"/>
        <inertia ixx="0.79449" ixy="0" ixz="0" iyy="1.21074" iyz="0" izz="1.56825"/>
      </inertial>
      <visual name="visual_chassis">
        <origin xyz="0 0 0" rpy="0 0 0"/>
        <geometry>
          <mesh filename="package://spear_simulator/models/rover/meshes/stl/TARS.V2.Chassis.stl" scale="0.001 0.001 0.001"/>
        </geometry>
      </visual>
      <collision name="collision_chassis">
        <origin xyz="0 0 0.19608" rpy="0 0 0"/>
        <geometry>
          <box size="0.63 0.48 0.29562"/>
        </geometry>
      </collision>
    </link>

    <link name="link_suspension_backleft">
      <inertial>
        <origin xyz="-0.12007 -0.01981 -0.04013" rpy="0 0 0"/>
        <mass value="0.75"/>
        <inertia ixx="0.00147" ixy="0" ixz="0" iyy="0.00598" iyz="0" izz="0.00469"/>
      </inertial>
      <visual name="visual_suspension_backleft">
        <origin xyz="0 0 0" rpy="0 0 -3.14159"/>
        <geometry>
          <mesh filename="package://spear_simulator/models/rover/meshes/stl/TARS.V2.Suspension.001.stl" scale="0.001 0.001 0.001"/>
        </geometry>
      </visual>
      <collision name="collision_suspension_backleft">
        <origin xyz="-0.12007 -0.01981 -0.04013" rpy="0 0 0"/>
        <geometry>
          <box size="0.27135 0.0381 0.14844"/>
        </geometry>
      </collision>
    </link>

    <link name="link_suspension_backright">
      <inertial>
        <origin xyz="-0.12007 0.02019 -0.04013" rpy="0 0 0"/>
        <mass value="0.75"/>
        <inertia ixx="0.00147" ixy="0" ixz="0" iyy="0.00598" iyz="0" izz="0.00469"/>
      </inertial>
      <visual name="visual_suspension_backright">
        <origin xyz="0 0 0" rpy="0 0 -3.14159"/>
        <geometry>
          <mesh filename="package://spear_simulator/models/rover/meshes/stl/TARS.V2.Suspension.001.stl" scale="0.001 0.001 0.001"/>
        </geometry>
      </visual>
      <collision name="collision_suspension_backright">
        <origin xyz="-0.12007 0.02019 -0.04013" rpy="0 0 0"/>
        <geometry>
          <box size="0.27135 0.0381 0.14844"/>
        </geometry>
      </collision>
    </link>

    <link name="link_suspension_frontleft">
      <inertial>
        <origin xyz="0.12007 -0.02019 -0.04013" rpy="0 0 0"/>
        <mass value="0.75"/>
        <inertia ixx="0.00147" ixy="0" ixz="0" iyy="0.00598" iyz="0" izz="0.00469"/>
      </inertial>
      <visual name="visual_suspension_frontleft">
        <origin xyz="0 0 0" rpy="0 0 0"/>
        <geometry>
          <mesh filename="package://spear_simulator/models/rover/meshes/stl/TARS.V2.Suspension.001.stl" scale="0.001 0.001 0.001"/>
        </geometry>
      </visual>
      <collision name="collision_suspension_frontleft">
        <origin xyz="0.12007 -0.02019 -0.04013" rpy="0 0 0"/>
        <geometry>
          <box size="0.27135 0.0381 0.14844"/>
        </geometry>
      </collision>
    </link>

    <link name="link_suspension_frontright">
      <inertial>
        <origin xyz="0.12007 0.01981 -0.04013" rpy="0 0 0"/>
        <mass value="0.75"/>
        <inertia ixx="0.00147" ixy="0" ixz="0" iyy="0.00598" iyz="0" izz="0.00469"/>
      </inertial>
      <visual name="visual_suspension_frontright">
        <origin xyz="0 0 0" rpy="0 0 0"/>
        <geometry>
          <mesh filename="package://spear_simulator/models/rover/meshes/stl/TARS.V2.Suspension.001.stl" scale="0.001 0.001 0.001"/>
        </geometry>
      </visual>
      <collision name="collision_suspension_frontright">
        <origin xyz="0.12007 0.01981 -0.04013" rpy="0 0 0"/>
        <geometry>
          <box size="0.27134 0.0381 0.14845"/>
        </geometry>
      </collision>
    </link>

    <link name="link_wheel_backleft">
      <inertial>
        <origin xyz="0 0.10244 0" rpy="0 0 0"/>
        <mass value="1.5"/>
        <inertia ixx="0.01534" ixy="0" ixz="0" iyy="0.01534" iyz="0" izz="0.01534"/>
      </inertial>
      <visual name="visual_wheel_backleft">
        <origin xyz="0 0 0" rpy="0 0 0"/>
        <geometry>
          <mesh filename="package://spear_simulator/models/rover/meshes/stl/TARS.V2.Wheel.001.stl" scale="0.001 0.001 0.001"/>
        </geometry>
      </visual>
      <collision name="collision_wheel_backleft">
        <origin xyz="0 0.10244 0" rpy="0 0 0"/>
        <geometry>
          <sphere radius="0.15989"/>
        </geometry>
      </collision>
    </link>

    <link name="link_wheel_backright">
      <inertial>
        <origin xyz="0 -0.10254 0" rpy="0 0 0"/>
        <mass value="1.5"/>
        <inertia ixx="0.01534" ixy="0" ixz="0" iyy="0.01534" iyz="0" izz="0.01534"/>
      </inertial>
      <visual name="visual_wheel_backright">
        <origin xyz="0 0 0" rpy="0 0 -3.14159"/>
        <geometry>
          <mesh filename="package://spear_simulator/models/rover/meshes/stl/TARS.V2.Wheel.001.stl" scale="0.001 0.001 0.001"/>
        </geometry>
      </visual>
      <collision name="collision_wheel_backright">
        <origin xyz="0 -0.10254 0" rpy="0 0 0"/>
        <geometry>
          <sphere radius="0.15989"/>
        </geometry>
      </collision>
    </link>

    <link name="link_wheel_frontleft">
      <inertial>
        <origin xyz="0 0.10244 0" rpy="0 0 0"/>
        <mass value="1.5"/>
        <inertia ixx="0.01534" ixy="0" ixz="0" iyy="0.01534" iyz="0" izz="0.01534"/>
      </inertial>
      <visual name="visual_wheel_frontleft">
        <origin xyz="0 0 0" rpy="0 0 0"/>
        <geometry>
          <mesh filename="package://spear_simulator/models/rover/meshes/stl/TARS.V2.Wheel.001.stl" scale="0.001 0.001 0.001"/>
        </geometry>
      </visual>
      <collision name="collision_wheel_frontleft">
        <origin xyz="0 0.10244 0" rpy="0 0 0"/>
        <geometry>
          <sphere radius="0.15989"/>
        </geometry>
      </collision>
    </link>

    <link name="link_wheel_frontright">
      <inertial>
        <origin xyz="0 -0.10264 0" rpy="0 0 0"/>
        <mass value="1.5"/>
        <inertia ixx="0.01534" ixy="0" ixz="0" iyy="0.01534" iyz="0" izz="0.01534"/>
      </inertial>
      <visual name="visual_wheel_frontright">
        <origin xyz="0 0 0" rpy="0 0 -3.14159"/>
        <geometry>
          <mesh filename="package://spear_simulator/models/rover/meshes/stl/TARS.V2.Wheel.001.stl" scale="0.001 0.001 0.001"/>
        </geometry>
      </visual>
      <collision name="collision_wheel_frontright">
        <origin xyz="0 -0.10264 0" rpy="0 0 0"/>
        <geometry>
          <sphere radius="0.15989"/>
        </geometry>
      </collision>
    </link>

    <joint name="link_camera_back" type="fixed">
      <origin xyz="-0.315 1e-05 0.3439" rpy="3.14159 1.5708 0"/>
      <parent link="base_link"/>
      <child link="link_camera_back"/>
    </joint>

    <joint name="link_camera_depth" type="fixed">
      <origin xyz="0.315 1e-05 0.3439" rpy="0 1.5708 0"/>
      <parent link="base_link"/>
      <child link="link_camera_depth"/>
    </joint>

    <joint name="link_camera_front" type="fixed">
      <origin xyz="0.315 -0.11999 0.3439" rpy="0 1.5708 0"/>
      <parent link="base_link"/>
      <child link="link_camera_front"/>
    </joint>

    <joint name="link_suspension_backleft" type="fixed">
      <origin xyz="-0.15754 0.25888 0.07402" rpy="0 0 0"/>
      <parent link="base_link"/>
      <child link="link_suspension_backleft"/>
    </joint>

    <joint name="link_suspension_backright" type="fixed">
      <origin xyz="-0.15754 -0.25922 0.07402" rpy="0 0 0"/>
      <parent link="base_link"/>
      <child link="link_suspension_backright"/>
    </joint>

    <joint name="link_suspension_frontleft" type="fixed">
      <origin xyz="0.15754 0.25925 0.07402" rpy="0 0 0"/>
      <parent link="base_link"/>
      <child link="link_suspension_frontleft"/>
    </joint>

    <joint name="link_suspension_frontright" type="fixed">
      <origin xyz="0.15755 -0.25885 0.07403" rpy="0 0 0"/>
      <parent link="base_link"/>
      <child link="link_suspension_frontright"/>
    </joint>

    <!-- Stuff to make the wheels driveable -->
    <joint name="link_wheel_backleft" type="continuous">
      <axis xyz="0 1 0" rpy="0 0 0"/>
      <origin xyz="-0.21346 0.01924 -0.08012" rpy="0 0 0"/>
      <parent link="link_suspension_backleft"/>
      <child link="link_wheel_backleft"/>
    </joint>
    <transmission name="wheel_backleft_trans">
      <type>transmission_interface/SimpleTransmission</type>
      <actuator name="wheel_backleft_motor">
        <mechanicalReduction>1</mechanicalReduction>
      </actuator>
      <joint name="link_wheel_backleft">
        <hardwareInterface>VelocityJointInterface</hardwareInterface>
      </joint>
    </transmission>
    <gazebo reference="link_wheel_backleft">
      <mu1 value="200.0"/>
      <mu2 value="100.0"/>
      <kp value="10000000.0" />
      <kd value="1.0" />
      <material>Gazebo/Grey</material>
    </gazebo>

    <joint name="link_wheel_backright" type="continuous">
      <axis xyz="0 1 0" rpy="0 0 0"/>
      <origin xyz="-0.21346 -0.01886 -0.08012" rpy="0 0 0"/>
      <parent link="link_suspension_backright"/>
      <child link="link_wheel_backright"/>
    </joint>
    <transmission name="wheel_backright_trans">
      <type>transmission_interface/SimpleTransmission</type>
      <actuator name="wheel_backright_motor">
        <mechanicalReduction>1</mechanicalReduction>
      </actuator>
      <joint name="link_wheel_backright">
        <hardwareInterface>VelocityJointInterface</hardwareInterface>
      </joint>
    </transmission>
    <gazebo reference="link_wheel_backright">
      <mu1 value="200.0"/>
      <mu2 value="100.0"/>
      <kp value="10000000.0" />
      <kd value="1.0" />
      <material>Gazebo/Grey</material>
    </gazebo>

    <joint name="link_wheel_frontleft" type="continuous">
      <axis xyz="0 1 0" rpy="0 0 0"/>
      <origin xyz="0.21346 0.01886 -0.08012" rpy="0 0 0"/>
      <parent link="link_suspension_frontleft"/>
      <child link="link_wheel_frontleft"/>
    </joint>
    <transmission name="wheel_frontleft_trans">
      <type>transmission_interface/SimpleTransmission</type>
      <actuator name="wheel_frontleft_motor">
        <mechanicalReduction>1</mechanicalReduction>
      </actuator>
      <joint name="link_wheel_frontleft">
        <hardwareInterface>VelocityJointInterface</hardwareInterface>
      </joint>
    </transmission>
    <gazebo reference="link_wheel_frontleft">
      <mu1 value="200.0"/>
      <mu2 value="100.0"/>
      <kp value="10000000.0" />
      <kd value="1.0" />
      <material>Gazebo/Grey</material>
    </gazebo>

    <joint name="link_wheel_frontright" type="continuous">
      <axis xyz="0 1 0" rpy="0 0 0"/>
      <origin xyz="0.21345 -0.01924 -0.08014" rpy="0 0 0"/>
      <parent link="link_suspension_frontright"/>
      <child link="link_wheel_frontright"/>
    </joint>
    <transmission name="wheel_frontright_trans">
      <type>transmission_interface/SimpleTransmission</type>
      <actuator name="wheel_frontright_motor">
        <mechanicalReduction>1</mechanicalReduction>
      </actuator>
      <joint name="link_wheel_frontright">
        <hardwareInterface>VelocityJointInterface</hardwareInterface>
      </joint>
    </transmission>
    <gazebo reference="link_wheel_frontright">
      <mu1 value="200.0"/>
      <mu2 value="100.0"/>
      <kp value="10000000.0" />
      <kd value="1.0" />
      <material>Gazebo/Grey</material>
    </gazebo>

    <gazebo>
      <plugin name="gazebo_ros_control" filename="libgazebo_ros_control.so">
        <robotNamespace>/</robotNamespace>
      </plugin>
    </gazebo>

  </robot>
